Workbook

Sheet Dashboard
A1: FUND ACCOUNTING | NAV & RECONCILIATION CONTROL DASHBOARD
A2: Excel / VBA control panel - Fund Accounting NAV & Reconciliation Control Engine
B4: As on (IST) -> | C4: 46301 | E4: Schemes: 3 | Window: last 30 business days | Source: SQL + Python engine
A6: TOTAL AUM | C6: WTD AVG NAV | E6: RECON MATCH RATE | G6: OPEN BREAKS | I6: SLA BREACHES | K6: CONTROLS PASSED
A7: =SUMIFS(NAV_Calc!$Q:$Q,NAV_Calc!$A:$A,$C$4)/10000000 | C7: =SUMPRODUCT((NAV_Calc!$A$5:$A$94=$C$4)*NAV_Calc!$R$5:$R$94,NAV_Calc!$Q$5:$Q$94)/SUMIFS(NAV_Calc!$Q:$Q,NAV_Calc!$A:$A,$C$4) | E7: =ChartData!$J$5/(ChartData!$J$5+ChartData!$J$6) | G7: =COUNTIF(Recon_Breaks!$P$5:$P$9,"OPEN") | I7: =COUNTIF(Recon_Breaks!$N$5:$N$9,"SLA_BREACH") | K7: =COUNTIF(Control_Panel!$F$5:$F$9,"PASS")&" / 5"
A8: 3 schemes | C8: AUM-weighted | E8: 110 items checked | G8: across 3 sources | I8: T+1 resolution SLA | K8: CHK01 - CHK05
A30: TOP OPEN BREAKS (live from Recon_Breaks)
A31: Break ID | B31: Fund | C31: Source | D31: Type | E31: Age (d) | F31: Impact | G31: SLA
A32: =Recon_Breaks!A5 | B32: =Recon_Breaks!B5 | C32: =Recon_Breaks!C5 | D32: =Recon_Breaks!D5 | E32: =Recon_Breaks!E5 | F32: =Recon_Breaks!F5 | G32: =Recon_Breaks!G5
A33: =Recon_Breaks!A6 | B33: =Recon_Breaks!B6 | C33: =Recon_Breaks!C6 | D33: =Recon_Breaks!D6 | E33: =Recon_Breaks!E6 | F33: =Recon_Breaks!F6 | G33: =Recon_Breaks!G6
A34: =Recon_Breaks!A7 | B34: =Recon_Breaks!B7 | C34: =Recon_Breaks!C7 | D34: =Recon_Breaks!D7 | E34: =Recon_Breaks!E7 | F34: =Recon_Breaks!F7 | G34: =Recon_Breaks!G7
A35: =Recon_Breaks!A8 | B35: =Recon_Breaks!B8 | C35: =Recon_Breaks!C8 | D35: =Recon_Breaks!D8 | E35: =Recon_Breaks!E8 | F35: =Recon_Breaks!F8 | G35: =Recon_Breaks!G8
A36: =Recon_Breaks!A9 | B36: =Recon_Breaks!B9 | C36: =Recon_Breaks!C9 | D36: =Recon_Breaks!D9 | E36: =Recon_Breaks!E9 | F36: =Recon_Breaks!F9 | G36: =Recon_Breaks!G9
A38: VBA: press Alt+F8 -> RunReconciliation / RefreshAllData / ExportOpenBreaksCSV (modules in vba/*.bas - see README_VBA_Setup.md)

Sheet Funds
A1: FUND MASTER
A2: Source: config / fundctl.Funds (SQL)
A4: fund_code | B4: fund_name | C4: category | D4: mgmt_fee_bps | E4: opening_nav | F4: opening_units | G4: opening_cash (formula)
A5: ALPHA_EQ | B5: Alpha Equity Fund | C5: Equity | D5: 150 | E5: 10 | F5: 10000000 | G5: =E5*F5-SUMIF(Opening_Holdings!$A$5:$A$21,A5,Opening_Holdings!$E$5:$E$21)
A6: BETA_DEBT | B6: Beta Debt Fund | C6: Debt | D6: 75 | E6: 10 | F6: 20000000 | G6: =E6*F6-SUMIF(Opening_Holdings!$A$5:$A$21,A6,Opening_Holdings!$E$5:$E$21)
A7: GAMMA_BAL | B7: Gamma Balanced Fund | C7: Hybrid | D7: 125 | E7: 10 | F7: 15000000 | G7: =E7*F7-SUMIF(Opening_Holdings!$A$5:$A$21,A7,Opening_Holdings!$E$5:$E$21)

Sheet Securities
A1: SECURITY MASTER
A2: Source: config / fundctl.Securities (SQL)
A4: symbol | B4: security_name | C4: sector | D4: asset_type | E4: base_price | F4: face_value
A5: HDFCBANK | B5: HDFC Bank Ltd | C5: Financials | D5: Equity | E5: 1650 | F5: 100
A6: ICICIBANK | B6: ICICI Bank Ltd | C6: Financials | D6: Equity | E6: 1250 | F6: 100
A7: INFY | B7: Infosys Ltd | C7: IT | D7: Equity | E7: 1550 | F7: 100
A8: TCS | B8: Tata Consultancy Svcs | C8: IT | D8: Equity | E8: 3600 | F8: 100
A9: RELIANCE | B9: Reliance Industries | C9: Energy | D9: Equity | E9: 1350 | F9: 100
A10: ITC | B10: ITC Ltd | C10: FMCG | D10: Equity | E10: 480 | F10: 100
A11: SBIN | B11: State Bank of India | C11: Financials | D11: Equity | E11: 620 | F11: 100
A12: LT | B12: Larsen & Toubro | C12: Infra | D12: Equity | E12: 2400 | F12: 100
A13: MARUTI | B13: Maruti Suzuki India | C13: Auto | D13: Equity | E13: 1800 | F13: 100
A14: HINDUNILVR | B14: Hindustan Unilever | C14: FMCG | D14: Equity | E14: 2600 | F14: 100
A15: GOI7.26-36 | B15: GOI 7.26% 2036 | C15: G-Sec | D15: Debt | E15: 102 | F15: 100
A16: GOI8.2-33 | B16: GOI 8.20% 2033 | C16: G-Sec | D16: Debt | E16: 108.5 | F16: 100
... A19: NCD-REL | B19: Reliance NCD 9.10% | C19: Corporate | D19: Debt | E19: 1005 | F19: 100

Sheet Opening_Holdings
A1: OPENING POSITIONS (T-30)
A2: Value = qty x base price (live formulas)
A4: fund_code | B4: symbol | C4: qty | D4: base_price (VLOOKUP) | E4: value (formula)
A5: ALPHA_EQ | B5: HDFCBANK | C5: 15200 | D5: =VLOOKUP($B5,Securities!$A$5:$E$19,5,FALSE) | E5: =C5*D5
A6: ALPHA_EQ | B6: ICICIBANK | C6: 16000 | D6: =VLOOKUP($B6,Securities!$A$5:$E$19,5,FALSE) | E6: =C6*D6
A7: ALPHA_EQ | B7: INFY | C7: 9700 | D7: =VLOOKUP($B7,Securities!$A$5:$E$19,5,FALSE) | E7: =C7*D7
A8: ALPHA_EQ | B8: TCS | C8: 4200 | D8: =VLOOKUP($B8,Securities!$A$5:$E$19,5,FALSE) | E8: =C8*D8
A9: ALPHA_EQ | B9: RELIANCE | C9: 7400 | D9: =VLOOKUP($B9,Securities!$A$5:$E$19,5,FALSE) | E9: =C9*D9
A10: ALPHA_EQ | B10: ITC | C10: 20800 | D10: =VLOOKUP($B10,Securities!$A$5:$E$19,5,FALSE) | E10: =C10*D10
A11: BETA_DEBT | B11: GOI7.26-36 | C11: 588200 | D11: =VLOOKUP($B11,Securities!$A$5:$E$19,5,FALSE) | E11: =C11*D11
A12: BETA_DEBT | B12: GOI8.2-33 | C12: 460800 | D12: =VLOOKUP($B12,Securities!$A$5:$E$19,5,FALSE) | E12: =C12*D12
A13: BETA_DEBT | B13: SDL-MH-32 | C13: 295600 | D13: =VLOOKUP($B13,Securities!$A$5:$E$19,5,FALSE) | E13: =C13*D13
A14: BETA_DEBT | B14: CP-TATA | C14: 200400 | D14: =VLOOKUP($B14,Securities!$A$5:$E$19,5,FALSE) | E14: =C14*D14
A15: BETA_DEBT | B15: NCD-REL | C15: 29900 | D15: =VLOOKUP($B15,Securities!$A$5:$E$19,5,FALSE) | E15: =C15*D15
A16: GAMMA_BAL | B16: HDFCBANK | C16: 18200 | D16: =VLOOKUP($B16,Securities!$A$5:$E$19,5,FALSE) | E16: =C16*D16
... A21: GAMMA_BAL | B21: SDL-MH-32 | C21: 221700 | D21: =VLOOKUP($B21,Securities!$A$5:$E$19,5,FALSE) | E21: =C21*D21

Sheet Transactions
A1: TRANSACTIONS (ALL EVENTS)
A2: Source: data/transactions.csv - loaded into fundctl.Transactions (SQL)
A4: txn_id | B4: txn_date | C4: fund_code | D4: txn_type | E4: counterparty | F4: units | G4: qty | H4: price | I4: cash_impact | J4: rate | K4: description
A5: 1 | B5: 46260 | C5: ALPHA_EQ | D5: REDEMPTION | E5: Ananya Gupta | F5: -12114.123 | I5: -121141.23 | J5: 10 | K5: Redemption by Ananya Gupta (AANJG3456F)
A6: 2 | B6: 46260 | C6: ALPHA_EQ | D6: SUBSCRIPTION | E6: Karan Singh | F6: 24899.383 | I6: 248993.83 | J6: 10 | K6: Subscription by Karan Singh (AKLSG4567G)
A7: 3 | B7: 46260 | C7: ALPHA_EQ | D7: TRADE | E7: ICICIBANK | G7: -200 | H7: 1226.9544 | I7: 245390.88 | K7: SELL 200 ICICIBANK @ 1226.9544
A8: 4 | B8: 46260 | C8: BETA_DEBT | D8: SUBSCRIPTION | E8: Aarav Sharma | F8: 41722.145 | I8: 417221.45 | J8: 10 | K8: Subscription by Aarav Sharma (AAAPS1234A)
A9: 5 | B9: 46260 | C9: BETA_DEBT | D9: TRADE | E9: CP-TATA | G9: 2000 | H9: 99.7675 | I9: -199535 | K9: BUY 2000 CP-TATA @ 99.7675
A10: 6 | B10: 46260 | C10: GAMMA_BAL | D10: REDEMPTION | E10: Vikram Reddy | F10: -29751.196 | I10: -297511.96 | J10: 10 | K10: Redemption by Vikram Reddy (AVBRS7890E)
A11: 7 | B11: 46260 | C11: GAMMA_BAL | D11: SUBSCRIPTION | E11: Aarav Sharma | F11: 26646.531 | I11: 266465.31 | J11: 10 | K11: Subscription by Aarav Sharma (AAAPS1234A)
A12: 8 | B12: 46260 | C12: GAMMA_BAL | D12: TRADE | E12: INFY | G12: -4000 | H12: 1570.1277 | I12: 6280510.8 | K12: SELL 4000 INFY @ 1570.1277
A13: 9 | B13: 46260 | C13: GAMMA_BAL | D13: TRADE | E13: SDL-MH-32 | G13: -3000 | H13: 101.345 | I13: 304035 | K13: SELL 3000 SDL-MH-32 @ 101.345
A14: 10 | B14: 46260 | C14: GAMMA_BAL | D14: TRADE | E14: SDL-MH-32 | G14: -200 | H14: 101.295 | I14: 20259 | K14: SELL 200 SDL-MH-32 @ 101.295
A15: 11 | B15: 46261 | C15: ALPHA_EQ | D15: REDEMPTION | E15: Karan Singh | F15: -10047.942 | I15: -100274.79 | J15: 9.9796 | K15: Redemption by Karan Singh (AKLSG4567G)
A16: 12 | B16: 46261 | C16: ALPHA_EQ | D16: TRADE | E16: TCS | G16: -4000 | H16: 3643.4017 | I16: 14573607 | K16: SELL 4000 TCS @ 3643.4017
A17: 13 | B17: 46261 | C17: ALPHA_EQ | D17: TRADE | E17: HDFCBANK | G17: 600 | H17: 1634.8268 | I17: -980896.08 | K17: BUY 600 HDFCBANK @ 1634.8268
A18: 14 | B18: 46261 | C18: BETA_DEBT | D18: SUBSCRIPTION | E18: Priya Nair | F18: 15737.064 | I18: 158054.33 | J18: 10.0434 | K18: Subscription by Priya Nair (ABCPN5678B)
A19: 15 | B19: 46261 | C19: BETA_DEBT | D19: TRADE | E19: SDL-MH-32 | G19: -800 | H19: 101.2528 | I19: 81002.24 | K19: SELL 800 SDL-MH-32 @ 101.2528
A20: 16 | B20: 46261 | C20: BETA_DEBT | D20: TRADE | E20: GOI7.26-36 | G20: -600 | H20: 102.9844 | I20: 61790.64 | K20: SELL 600 GOI7.26-36 @ 102.9844
A21: 17 | B21: 46261 | C21: BETA_DEBT | D21: TRADE | E21: CP-TATA | G21: 1000 | H21: 99.8151 | I21: -99815.1 | K21: BUY 1000 CP-TATA @ 99.8151
A22: 18 | B22: 46261 | C22: GAMMA_BAL | D22: REDEMPTION | E22: Vikram Reddy | F22: -35174.725 | I22: -349361.9 | J22: 9.9322 | K22: Redemption by Vikram Reddy (AVBRS7890E)
A23: 19 | B23: 46261 | C23: GAMMA_BAL | D23: SUBSCRIPTION | E23: Ananya Gupta | F23: 8075.2557 | I23: 80204.94 | J23: 9.9322 | K23: Subscription by Ananya Gupta (AANJG3456F)
A24: 20 | B24: 46261 | C24: GAMMA_BAL | D24: TRADE | E24: HDFCBANK | G24: -500 | H24: 1633.7538 | I24: 816876.9 | K24: SELL 500 HDFCBANK @ 1633.7538
A25: 21 | B25: 46262 | C25: ALPHA_EQ | D25: TRADE | E25: ITC | G25: -4000 | H25: 473.7985 | I25: 1895194 | K25: SELL 4000 ITC @ 473.7985
A26: 22 | B26: 46262 | C26: ALPHA_EQ | D26: TRADE | E26: HDFCBANK | G26: 1000 | H26: 1658.0993 | I26: -1658099.3 | K26: BUY 1000 HDFCBANK @ 1658.0993
A27: 23 | B27: 46262 | C27: BETA_DEBT | D27: REDEMPTION | E27: Meera Joshi | F27: -29467.375 | I27: -295994.76 | J27: 10.0448 | K27: Redemption by Meera Joshi (MMJMJ7890K)
A28: 24 | B28: 46262 | C28: BETA_DEBT | D28: SUBSCRIPTION | E28: Meera Joshi | F28: 20612.805 | I28: 207052.12 | J28: 10.0448 | K28: Subscription by Meera Joshi (MMJMJ7890K)
A29: 25 | B29: 46262 | C29: BETA_DEBT | D29: TRADE | E29: GOI8.2-33 | G29: -800 | H29: 108.7414 | I29: 86993.12 | K29: SELL 800 GOI8.2-33 @ 108.7414
A30: 26 | B30: 46262 | C30: GAMMA_BAL | D30: REDEMPTION | E30: Rahul Mehta | F30: -35731.842 | I30: -357500.56 | J30: 10.0051 | K30: Redemption by Rahul Mehta (ACARM6789C)
A31: 27 | B31: 46262 | C31: GAMMA_BAL | D31: TRADE | E31: HDFCBANK | G31: -400 | H31: 1655.7083 | I31: 662283.32 | K31: SELL 400 HDFCBANK @ 1655.7083
A32: 28 | B32: 46262 | C32: GAMMA_BAL | D32: TRADE | E32: MARUTI | G32: -1200 | H32: 1835.318 | I32: 2202381.6 | K32: SELL 1200 MARUTI @ 1835.318
A33: 29 | B33: 46265 | C33: ALPHA_EQ | D33: TRADE | E33: RELIANCE | G33: 2500 | H33: 1451.5667 | I33: -3628916.8 | K33: BUY 2500 RELIANCE @ 1451.5667
A34: 30 | B34: 46265 | C34: ALPHA_EQ | D34: TRADE | E34: HDFCBANK | G34: 3000 | H34: 1649.6733 | I34: -4949019.9 | K34: BUY 3000 HDFCBANK @ 1649.6733
A35: 31 | B35: 46265 | C35: BETA_DEBT | D35: SUBSCRIPTION | E35: Arjun Patel | F35: 14374.497 | I35: 144931.75 | J35: 10.0826 | K35: Subscription by Arjun Patel (APAPL6789I)
A36: 32 | B36: 46265 | C36: BETA_DEBT | D36: TRADE | E36: NCD-REL | G36: 3000 | H36: 1003.9723 | I36: -3011916.9 | K36: BUY 3000 NCD-REL @ 1003.9723
A37: 33 | B37: 46265 | C37: BETA_DEBT | D37: TRADE | E37: CP-TATA | G37: 4000 | H37: 99.9297 | I37: -399718.8 | K37: BUY 4000 CP-TATA @ 99.9297
A38: 34 | B38: 46265 | C38: GAMMA_BAL | D38: REDEMPTION | E38: Rahul Mehta | F38: -39008.137 | I38: -388431.44 | J38: 9.9577 | K38: Redemption by Rahul Mehta (ACARM6789C)
A39: 35 | B39: 46265 | C39: GAMMA_BAL | D39: TRADE | E39: HDFCBANK | G39: -800 | H39: 1649.6863 | I39: 1319749 | K39: SELL 800 HDFCBANK @ 1649.6863
A40: 36 | B40: 46266 | C40: ALPHA_EQ | D40: SUBSCRIPTION | E40: Arjun Patel | F40: 15934.637 | I40: 157718.43 | J40: 9.8978 | K40: Subscription by Arjun Patel (APAPL6789I)
A41: 37 | B41: 46266 | C41: ALPHA_EQ | D41: TRADE | E41: ITC | G41: -3000 | H41: 485.4189 | I41: 1456256.7 | K41: SELL 3000 ITC @ 485.4189
...

Sheet Price_Matrix
A1: PRICE MATRIX (CLOSE,securities x dates)
A2: Source: data/prices.csv - loaded into fundctl.PriceHistory (SQL)
A4: symbol | B4: 46260 | C4: 46261 | D4: 46262 | E4: 46265 | F4: 46266 | G4: 46267 | H4: 46268 | I4: 46269 | J4: 46272 | K4: 46273 | L4: 46274 | M4: 46275 | N4: 46276 | O4: 46279 | P4: 46280 | Q4: 46281 | R4: 46282 | S4: 46283 | T4: 46286 | U4: 46287 | V4: 46288 | W4: 46289 | X4: 46290 | Y4: 46293 | Z4: 46294 | AA4: 46295 | AB4: 46296 | AC4: 46297 | AD4: 46300 | AE4: 46301
A5: HDFCBANK | B5: 1626.9184 | C5: 1635.4289 | D5: 1656.1007 | E5: 1647.0608 | F5: 1621.9468 | G5: 1621.8068 | H5: 1632.245 | I5: 1654.8976 | J5: 1631.9103 | K5: 1607.7345 | L5: 1622.4793 | M5: 1632.8454 | N5: 1664.0416 | O5: 1684.8246 | P5: 1683.9462 | Q5: 1679.5834 | R5: 1732.5681 | S5: 1727.7764 | T5: 1712.7116 | U5: 1690.5146 | V5: 1693.6345 | W5: 1697.7734 | X5: 1691.9358 | Y5: 1691.8581 | Z5: 1698.5868 | AA5: 1713.889 | AB5: 1737.6463 | AC5: 1743.2376 | AD5: 1707.0177 | AE5: 1722.5869
A6: ICICIBANK | B6: 1227.8049 | C6: 1225.9283 | D6: 1203.2985 | E6: 1204.1736 | F6: 1192.8287 | G6: 1196.9804 | H6: 1249.1735 | I6: 1249.2586 | J6: 1263.8127 | K6: 1242.9557 | L6: 1239.1713 | M6: 1250.7109 | N6: 1250.0796 | O6: 1256.9705 | P6: 1259.5388 | Q6: 1243.9461 | R6: 1253.9333 | S6: 1241.5741 | T6: 1272.6542 | U6: 1265.1867 | V6: 1277.3568 | W6: 1278.2899 | X6: 1295.012 | Y6: 1285.7812 | Z6: 1303.3775 | AA6: 1302.1905 | AB6: 1324.4879 | AC6: 1336.1626 | AD6: 1339.5522 | AE6: 1326.9019
A7: INFY | B7: 1567.7463 | C7: 1579.119 | D7: 1616.5228 | E7: 1609.1218 | F7: 1622.7456 | G7: 1635.421 | H7: 1643.0447 | I7: 1648.9897 | J7: 1654.3485 | K7: 1641.6471 | L7: 1619.4807 | M7: 1611.6253 | N7: 1626.0839 | O7: 1661.6246 | P7: 1685.5176 | Q7: 1711.5513 | R7: 1731.3747 | S7: 1749.5173 | T7: 1755.2328 | U7: 1775.4202 | V7: 1820.7494 | W7: 1813.6725 | X7: 1797.3254 | Y7: 1847.9043 | Z7: 1855.5281 | AA7: 1882.0503 | AB7: 1906.3929 | AC7: 1877.4153 | AD7: 1942.6906 | AE7: 1992.3485
A8: TCS | B8: 3609.527 | C8: 3641.9314 | D8: 3649.5649 | E8: 3616.6249 | F8: 3614.6988 | G8: 3632.1016 | H8: 3679.2238 | I8: 3710.5042 | J8: 3715.5307 | K8: 3773.5031 | L8: 3744.5683 | M8: 3779.8491 | N8: 3828.7378 | O8: 3819.1194 | P8: 3746.5683 | Q8: 3711.8403 | R8: 3724.1162 | S8: 3748.3461 | T8: 3814.8056 | U8: 3775.338 | V8: 3778.0657 | W8: 3807.6738 | X8: 3803.7341 | Y8: 3707.2458 | Z8: 3742.7283 | AA8: 3840.5437 | AB8: 3885.6602 | AC8: 3849.1668 | AD8: 3834.4002 | AE8: 3846.4404
A9: RELIANCE | B9: 1401.3482 | C9: 1415.3069 | D9: 1418.7103 | E9: 1452.848 | F9: 1452.0845 | G9: 1493.6437 | H9: 1479.342 | I9: 1469.8413 | J9: 1486.7637 | K9: 1519.5697 | L9: 1535.5386 | M9: 1543.56 | N9: 1502.4636 | O9: 1487.4497 | P9: 1474.8666 | Q9: 1464.0939 | R9: 1477.9978 | S9: 1471.6014 | T9: 1490.0187 | U9: 1492.9018 | V9: 1486.4941 | W9: 1490.1692 | X9: 1500.7961 | Y9: 1521.1649 | Z9: 1511.3343 | AA9: 1507.117 | AB9: 1477.3449 | AC9: 1513.92 | AD9: 1547.948 | AE9: 1544.8792
A10: ITC | B10: 478.0398 | C10: 472.4664 | D10: 473.5998 | E10: 474.9083 | F10: 485.602 | G10: 487.1381 | H10: 483.6898 | I10: 472.2039 | J10: 479.1896 | K10: 480.4326 | L10: 473.0373 | M10: 474.2217 | N10: 466.9254 | O10: 483.5031 | P10: 489.2516 | Q10: 492.3949 | R10: 491.8774 | S10: 481.6969 | T10: 481.4252 | U10: 474.2781 | V10: 477.4378 | W10: 467.5602 | X10: 463.6433 | Y10: 469.6223 | Z10: 477.671 | AA10: 472.3631 | AB10: 465.4479 | AC10: 469.8669 | AD10: 474.2041 | AE10: 469.8578
A11: SBIN | B11: 613.5466 | C11: 607.1637 | D11: 596.0339 | E11: 589.9643 | F11: 602.1836 | G11: 609.25 | H11: 629.7242 | I11: 629.2951 | J11: 628.3726 | K11: 618.9353 | L11: 618.1425 | M11: 605.5883 | N11: 588.7904 | O11: 595.7685 | P11: 609.9131 | Q11: 618.5067 | R11: 632.1254 | S11: 635.1202 | T11: 628.2662 | U11: 629.574 | V11: 626.2469 | W11: 615.5481 | X11: 599.3101 | Y11: 585.5115 | Z11: 585.8696 | AA11: 587.6924 | AB11: 583.6413 | AC11: 597.3942 | AD11: 599.5233 | AE11: 605.5335
A12: LT | B12: 2439.7003 | C12: 2415.3975 | D12: 2355.236 | E12: 2379.9206 | F12: 2360.2867 | G12: 2402.1646 | H12: 2414.3879 | I12: 2447.675 | J12: 2473.6885 | K12: 2408.5133 | L12: 2432.7188 | M12: 2413.1341 | N12: 2391.1036 | O12: 2379.2523 | P12: 2404.6771 | Q12: 2434.0072 | R12: 2467.7097 | S12: 2416.1937 | T12: 2399.3349 | U12: 2326.9214 | V12: 2325.4645 | W12: 2345.2349 | X12: 2323.5838 | Y12: 2332.6047 | Z12: 2341.253 | AA12: 2373.56 | AB12: 2349.8762 | AC12: 2326.1964 | AD12: 2304.7428 | AE12: 2358.8666
A13: MARUTI | B13: 1828.7433 | C13: 1826.8584 | D13: 1833.9075 | E13: 1838.128 | F13: 1844.6392 | G13: 1840.5424 | H13: 1833.2197 | I13: 1802.253 | J13: 1787.3201 | K13: 1829.8682 | L13: 1844.8948 | M13: 1847.8587 | N13: 1843.5947 | O13: 1846.5024 | P13: 1856.9294 | Q13: 1841.4372 | R13: 1847.7881 | S13: 1855.2905 | T13: 1837.145 | U13: 1818.138 | V13: 1793.9825 | W13: 1768.5317 | X13: 1791.8026 | Y13: 1733.8518 | Z13: 1728.5898 | AA13: 1715.0105 | AB13: 1701.3291 | AC13: 1704.8447 | AD13: 1732.9594 | AE13: 1736.0266
A14: HINDUNILVR | B14: 2598.5383 | C14: 2586.0352 | D14: 2584.844 | E14: 2607.8713 | F14: 2600.4482 | G14: 2575.4362 | H14: 2547.9376 | I14: 2524.3425 | J14: 2494.5318 | K14: 2520.9523 | L14: 2530.7756 | M14: 2527.1406 | N14: 2562.1054 | O14: 2548.7294 | P14: 2567.7866 | Q14: 2588.0944 | R14: 2553.8889 | S14: 2519.8897 | T14: 2500.6187 | U14: 2522.7756 | V14: 2553.9695 | W14: 2527.5407 | X14: 2553.162 | Y14: 2546.1478 | Z14: 2538.9137 | AA14: 2528.0975 | AB14: 2522.4953 | AC14: 2482.9805 | AD14: 2462.3438 | AE14: 2436.6844
A15: GOI7.26-36 | B15: 102.1623 | C15: 102.8149 | D15: 103.6698 | E15: 103.5776 | F15: 103.0551 | G15: 102.9417 | H15: 102.6639 | I15: 103.2871 | J15: 103.4764 | K15: 103.2626 | L15: 103.5649 | M15: 103.7438 | N15: 103.2504 | O15: 103.0982 | P15: 103.0366 | Q15: 103.0548 | R15: 103.108 | S15: 103.0155 | T15: 103.0865 | U15: 102.9176 | V15: 102.6532 | W15: 103.1323 | X15: 103.2561 | Y15: 103.4043 | Z15: 102.9219 | AA15: 102.883 | AB15: 103.1482 | AC15: 102.761 | AD15: 103.1117 | AE15: 103.0036
... A19: NCD-REL | B19: 1007.1973 | C19: 1003.6517 | D19: 1004.2894 | E19: 1002.3904 | F19: 997.5168 | G19: 1001.1162 | H19: 1003.9018 | I19: 1004.3218 | J19: 1000.7969 | K19: 992.8874 | L19: 994.9347 | M19: 994.6651 | N19: 988.0851 | O19: 987.966 | P19: 982.073 | Q19: 982.0863 | R19: 982.766 | S19: 984.2786 | T19: 985.2512 | U19: 986.043 | V19: 981.6655 | W19: 980.2768 | X19: 978.3897 | Y19: 977.5848 | Z19: 978.7579 | AA19: 981.2989 | AB19: 987.8344 | AC19: 977.8031 | AD19: 979.4889 | AE19: 978.8293

Sheet Holdings_EOD
A1: END-OF-DAY HOLDINGS (ENGINE FEED)
A2: Source: outputs/holdings_eod.csv - mirrors fundctl.HoldingsEOD
A4: nav_date | B4: fund_code | C4: symbol | D4: qty | E4: close_price | F4: market_value
A5: 46260 | B5: ALPHA_EQ | C5: HDFCBANK | D5: 15200 | E5: 1626.9184 | F5: 24729160
A6: 46260 | B6: ALPHA_EQ | C6: ICICIBANK | D6: 15800 | E6: 1227.8049 | F6: 19399317
A7: 46260 | B7: ALPHA_EQ | C7: INFY | D7: 9700 | E7: 1567.7463 | F7: 15207139
A8: 46260 | B8: ALPHA_EQ | C8: TCS | D8: 4200 | E8: 3609.527 | F8: 15160013
A9: 46260 | B9: ALPHA_EQ | C9: RELIANCE | D9: 7400 | E9: 1401.3482 | F9: 10369977
A10: 46260 | B10: ALPHA_EQ | C10: ITC | D10: 20800 | E10: 478.0398 | F10: 9943227.8
A11: 46261 | B11: ALPHA_EQ | C11: HDFCBANK | D11: 15800 | E11: 1635.4289 | F11: 25839777
A12: 46261 | B12: ALPHA_EQ | C12: ICICIBANK | D12: 15800 | E12: 1225.9283 | F12: 19369667
A13: 46261 | B13: ALPHA_EQ | C13: INFY | D13: 9700 | E13: 1579.119 | F13: 15317454
A14: 46261 | B14: ALPHA_EQ | C14: TCS | D14: 200 | E14: 3641.9314 | F14: 728386.28
A15: 46261 | B15: ALPHA_EQ | C15: RELIANCE | D15: 7400 | E15: 1415.3069 | F15: 10473271
A16: 46261 | B16: ALPHA_EQ | C16: ITC | D16: 20800 | E16: 472.4664 | F16: 9827301.1
... A514: 46301 | B514: GAMMA_BAL | C514: SDL-MH-32 | D514: 212900 | E514: 104.457 | F514: 22238895

Sheet NAV_Calc
A1: DAILY NAV CALCULATION (LIVE FORMULAS)
A2: NAV = (Cash + HoldingsValue - AccruedLiab) / UnitsClose. HoldingsValue is the engine EOD feed (Holdings_EOD x Price_Matrix). Flows are allocated at T-1 application NAV.
A4: nav_date | B4: fund_code | C4: fund_name | D4: units_open | E4: sub_units | F4: red_units | G4: units_close | H4: cash_open | I4: net_cash_flows | J4: fee_paid | K4: cash_close | L4: holdings_value | M4: total_assets | N4: prev_net_assets | O4: fee_accrual | P4: accrued_liab | Q4: net_assets | R4: nav | S4: daily_return_pct
A5: 46260 | B5: ALPHA_EQ | C5: =VLOOKUP($B5,Funds!$A$5:$B$7,2,FALSE) | D5: =VLOOKUP($B5,Funds!$A$5:$F$7,6,FALSE) | E5: =SUMIFS(Transactions!$F:$F,Transactions!$C:$C,$B5,Transactions!$B:$B,$A5,Transactions!$D:$D,"SUBSCRIPTION") | F5: =-SUMIFS(Transactions!$F:$F,Transactions!$C:$C,$B5,Transactions!$B:$B,$A5,Transactions!$D:$D,"REDEMPTION") | G5: =D5+E5+F5 | H5: =VLOOKUP($B5,Funds!$A$5:$G$7,7,FALSE) | I5: =SUMIFS(Transactions!$I:$I,Transactions!$C:$C,$B5,Transactions!$B:$B,$A5) | J5: =IF($A5=EOMONTH($A5,0),O5,0) | K5: =H5+I5-J5 | L5: 94808834 | M5: =K5+L5 | N5: =VLOOKUP($B5,Funds!$A$5:$E$7,5,FALSE)*VLOOKUP($B5,Funds!$A$5:$F$7,6,FALSE) | O5: =N5*VLOOKUP($B5,Funds!$A$5:$D$7,4,FALSE)/36500 | P5: =O5-J5 | Q5: =M5-P5 | R5: =Q5/G5 | S5: =R5/VLOOKUP($B5,Funds!$A$5:$E$7,5,FALSE)-1
A6: 46261 | B6: ALPHA_EQ | C6: =VLOOKUP($B6,Funds!$A$5:$B$7,2,FALSE) | D6: =G5 | E6: =SUMIFS(Transactions!$F:$F,Transactions!$C:$C,$B6,Transactions!$B:$B,$A6,Transactions!$D:$D,"SUBSCRIPTION") | F6: =-SUMIFS(Transactions!$F:$F,Transactions!$C:$C,$B6,Transactions!$B:$B,$A6,Transactions!$D:$D,"REDEMPTION") | G6: =D6+E6+F6 | H6: =K5 | I6: =SUMIFS(Transactions!$I:$I,Transactions!$C:$C,$B6,Transactions!$B:$B,$A6) | J6: =IF($A6=EOMONTH($A6,0),P5+O6,0) | K6: =H6+I6-J6 | L6: 81555857 | M6: =K6+L6 | N6: =Q5 | O6: =N6*VLOOKUP($B6,Funds!$A$5:$D$7,4,FALSE)/36500 | P6: =P5+O6-J6 | Q6: =M6-P6 | R6: =Q6/G6 | S6: =R6/R5-1
A7: 46262 | B7: ALPHA_EQ | C7: =VLOOKUP($B7,Funds!$A$5:$B$7,2,FALSE) | D7: =G6 | E7: =SUMIFS(Transactions!$F:$F,Transactions!$C:$C,$B7,Transactions!$B:$B,$A7,Transactions!$D:$D,"SUBSCRIPTION") | F7: =-SUMIFS(Transactions!$F:$F,Transactions!$C:$C,$B7,Transactions!$B:$B,$A7,Transactions!$D:$D,"REDEMPTION") | G7: =D7+E7+F7 | H7: =K6 | I7: =SUMIFS(Transactions!$I:$I,Transactions!$C:$C,$B7,Transactions!$B:$B,$A7) | J7: =IF($A7=EOMONTH($A7,0),P6+O7,0) | K7: =H7+I7-J7 | L7: 81699725 | M7: =K7+L7 | N7: =Q6 | O7: =N7*VLOOKUP($B7,Funds!$A$5:$D$7,4,FALSE)/36500 | P7: =P6+O7-J7 | Q7: =M7-P7 | R7: =Q7/G7 | S7: =R7/R6-1
A8: 46265 | B8: ALPHA_EQ | C8: =VLOOKUP($B8,Funds!$A$5:$B$7,2,FALSE) | D8: =G7 | E8: =SUMIFS(Transactions!$F:$F,Transactions!$C:$C,$B8,Transactions!$B:$B,$A8,Transactions!$D:$D,"SUBSCRIPTION") | F8: =-SUMIFS(Transactions!$F:$F,Transactions!$C:$C,$B8,Transactions!$B:$B,$A8,Transactions!$D:$D,"REDEMPTION") | G8: =D8+E8+F8 | H8: =K7 | I8: =SUMIFS(Transactions!$I:$I,Transactions!$C:$C,$B8,Transactions!$B:$B,$A8) | J8: =IF($A8=EOMONTH($A8,0),P7+O8,0) | K8: =H8+I8-J8 | L8: 90331208 | M8: =K8+L8 | N8: =Q7 | O8: =N8*VLOOKUP($B8,Funds!$A$5:$D$7,4,FALSE)/36500 | P8: =P7+O8-J8 | Q8: =M8-P8 | R8: =Q8/G8 | S8: =R8/R7-1
A9: 46266 | B9: ALPHA_EQ | C9: =VLOOKUP($B9,Funds!$A$5:$B$7,2,FALSE) | D9: =G8 | E9: =SUMIFS(Transactions!$F:$F,Transactions!$C:$C,$B9,Transactions!$B:$B,$A9,Transactions!$D:$D,"SUBSCRIPTION") | F9: =-SUMIFS(Transactions!$F:$F,Transactions!$C:$C,$B9,Transactions!$B:$B,$A9,Transactions!$D:$D,"REDEMPTION") | G9: =D9+E9+F9 | H9: =K8 | I9: =SUMIFS(Transactions!$I:$I,Transactions!$C:$C,$B9,Transactions!$B:$B,$A9) | J9: =IF($A9=EOMONTH($A9,0),P8+O9,0) | K9: =H9+I9-J9 | L9: 89604091 | M9: =K9+L9 | N9: =Q8 | O9: =N9*VLOOKUP($B9,Funds!$A$5:$D$7,4,FALSE)/36500 | P9: =P8+O9-J9 | Q9: =M9-P9 | R9: =Q9/G9 | S9: =R9/R8-1
A10: 46267 | B10: ALPHA_EQ | C10: =VLOOKUP($B10,Funds!$A$5:$B$7,2,FALSE) | D10: =G9 | E10: =SUMIFS(Transactions!$F:$F,Transactions!$C:$C,$B10,Transactions!$B:$B,$A10,Transactions!$D:$D,"SUBSCRIPTION") | F10: =-SUMIFS(Transactions!$F:$F,Transactions!$C:$C,$B10,Transactions!$B:$B,$A10,Transactions!$D:$D,"REDEMPTION") | G10: =D10+E10+F10 | H10: =K9 | I10: =SUMIFS(Transactions!$I:$I,Transactions!$C:$C,$B10,Transactions!$B:$B,$A10) | J10: =IF($A10=EOMONTH($A10,0),P9+O10,0) | K10: =H10+I10-J10 | L10: 96585937 | M10: =K10+L10 | N10: =Q9 | O10: =N10*VLOOKUP($B10,Funds!$A$5:$D$7,4,FALSE)/36500 | P10: =P9+O10-J10 | Q10: =M10-P10 | R10: =Q10/G10 | S10: =R10/R9-1
A11: 46268 | B11: ALPHA_EQ | C11: =VLOOKUP($B11,Funds!$A$5:$B$7,2,FALSE) | D11: =G10 | E11: =SUMIFS(Transactions!$F:$F,Transactions!$C:$C,$B11,Transactions!$B:$B,$A11,Transactions!$D:$D,"SUBSCRIPTION") | F11: =-SUMIFS(Transactions!$F:$F,Transactions!$C:$C,$B11,Transactions!$B:$B,$A11,Transactions!$D:$D,"REDEMPTION") | G11: =D11+E11+F11 | H11: =K10 | I11: =SUMIFS(Transactions!$I:$I,Transactions!$C:$C,$B11,Transactions!$B:$B,$A11) | J11: =IF($A11=EOMONTH($A11,0),P10+O11,0) | K11: =H11+I11-J11 | L11: 98431013 | M11: =K11+L11 | N11: =Q10 | O11: =N11*VLOOKUP($B11,Funds!$A$5:$D$7,4,FALSE)/36500 | P11: =P10+O11-J11 | Q11: =M11-P11 | R11: =Q11/G11 | S11: =R11/R10-1
A12: 46269 | B12: ALPHA_EQ | C12: =VLOOKUP($B12,Funds!$A$5:$B$7,2,FALSE) | D12: =G11 | E12: =SUMIFS(Transactions!$F:$F,Transactions!$C:$C,$B12,Transactions!$B:$B,$A12,Transactions!$D:$D,"SUBSCRIPTION") | F12: =-SUMIFS(Transactions!$F:$F,Transactions!$C:$C,$B12,Transactions!$B:$B,$A12,Transactions!$D:$D,"REDEMPTION") | G12: =D12+E12+F12 | H12: =K11 | I12: =SUMIFS(Transactions!$I:$I,Transactions!$C:$C,$B12,Transactions!$B:$B,$A12) | J12: =IF($A12=EOMONTH($A12,0),P11+O12,0) | K12: =H12+I12-J12 | L12: 1.0672518e+08 | M12: =K12+L12 | N12: =Q11 | O12: =N12*VLOOKUP($B12,Funds!$A$5:$D$7,4,FALSE)/36500 | P12: =P11+O12-J12 | Q12: =M12-P12 | R12: =Q12/G12 | S12: =R12/R11-1
A13: 46272 | B13: ALPHA_EQ | C13: =VLOOKUP($B13,Funds!$A$5:$B$7,2,FALSE) | D13: =G12 | E13: =SUMIFS(Transactions!$F:$F,Transactions!$C:$C,$B13,Transactions!$B:$B,$A13,Transactions!$D:$D,"SUBSCRIPTION") | F13: =-SUMIFS(Transactions!$F:$F,Transactions!$C:$C,$B13,Transactions!$B:$B,$A13,Transactions!$D:$D,"REDEMPTION") | G13: =D13+E13+F13 | H13: =K12 | I13: =SUMIFS(Transactions!$I:$I,Transactions!$C:$C,$B13,Transactions!$B:$B,$A13) | J13: =IF($A13=EOMONTH($A13,0),P12+O13,0) | K13: =H13+I13-J13 | L13: 92578406 | M13: =K13+L13 | N13: =Q12 | O13: =N13*VLOOKUP($B13,Funds!$A$5:$D$7,4,FALSE)/36500 | P13: =P12+O13-J13 | Q13: =M13-P13 | R13: =Q13/G13 | S13: =R13/R12-1
A14: 46273 | B14: ALPHA_EQ | C14: =VLOOKUP($B14,Funds!$A$5:$B$7,2,FALSE) | D14: =G13 | E14: =SUMIFS(Transactions!$F:$F,Transactions!$C:$C,$B14,Transactions!$B:$B,$A14,Transactions!$D:$D,"SUBSCRIPTION") | F14: =-SUMIFS(Transactions!$F:$F,Transactions!$C:$C,$B14,Transactions!$B:$B,$A14,Transactions!$D:$D,"REDEMPTION") | G14: =D14+E14+F14 | H14: =K13 | I14: =SUMIFS(Transactions!$I:$I,Transactions!$C:$C,$B14,Transactions!$B:$B,$A14) | J14: =IF($A14=EOMONTH($A14,0),P13+O14,0) | K14: =H14+I14-J14 | L14: 94238690 | M14: =K14+L14 | N14: =Q13 | O14: =N14*VLOOKUP($B14,Funds!$A$5:$D$7,4,FALSE)/36500 | P14: =P13+O14-J14 | Q14: =M14-P14 | R14: =Q14/G14 | S14: =R14/R13-1
A15: 46274 | B15: ALPHA_EQ | C15: =VLOOKUP($B15,Funds!$A$5:$B$7,2,FALSE) | D15: =G14 | E15: =SUMIFS(Transactions!$F:$F,Transactions!$C:$C,$B15,Transactions!$B:$B,$A15,Transactions!$D:$D,"SUBSCRIPTION") | F15: =-SUMIFS(Transactions!$F:$F,Transactions!$C:$C,$B15,Transactions!$B:$B,$A15,Transactions!$D:$D,"REDEMPTION") | G15: =D15+E15+F15 | H15: =K14 | I15: =SUMIFS(Transactions!$I:$I,Transactions!$C:$C,$B15,Transactions!$B:$B,$A15) | J15: =IF($A15=EOMONTH($A15,0),P14+O15,0) | K15: =H15+I15-J15 | L15: 92534922 | M15: =K15+L15 | N15: =Q14 | O15: =N15*VLOOKUP($B15,Funds!$A$5:$D$7,4,FALSE)/36500 | P15: =P14+O15-J15 | Q15: =M15-P15 | R15: =Q15/G15 | S15: =R15/R14-1
A16: 46275 | B16: ALPHA_EQ | C16: =VLOOKUP($B16,Funds!$A$5:$B$7,2,FALSE) | D16: =G15 | E16: =SUMIFS(Transactions!$F:$F,Transactions!$C:$C,$B16,Transactions!$B:$B,$A16,Transactions!$D:$D,"SUBSCRIPTION") | F16: =-SUMIFS(Transactions!$F:$F,Transactions!$C:$C,$B16,Transactions!$B:$B,$A16,Transactions!$D:$D,"REDEMPTION") | G16: =D16+E16+F16 | H16: =K15 | I16: =SUMIFS(Transactions!$I:$I,Transactions!$C:$C,$B16,Transactions!$B:$B,$A16) | J16: =IF($A16=EOMONTH($A16,0),P15+O16,0) | K16: =H16+I16-J16 | L16: 92967397 | M16: =K16+L16 | N16: =Q15 | O16: =N16*VLOOKUP($B16,Funds!$A$5:$D$7,4,FALSE)/36500 | P16: =P15+O16-J16 | Q16: =M16-P16 | R16: =Q16/G16 | S16: =R16/R15-1
A17: 46276 | B17: ALPHA_EQ | C17: =VLOOKUP($B17,Funds!$A$5:$B$7,2,FALSE) | D17: =G16 | E17: =SUMIFS(Transactions!$F:$F,Transactions!$C:$C,$B17,Transactions!$B:$B,$A17,Transactions!$D:$D,"SUBSCRIPTION") | F17: =-SUMIFS(Transactions!$F:$F,Transactions!$C:$C,$B17,Transactions!$B:$B,$A17,Transactions!$D:$D,"REDEMPTION") | G17: =D17+E17+F17 | H17: =K16 | I17: =SUMIFS(Transactions!$I:$I,Transactions!$C:$C,$B17,Transactions!$B:$B,$A17) | J17: =IF($A17=EOMONTH($A17,0),P16+O17,0) | K17: =H17+I17-J17 | L17: 89834854 | M17: =K17+L17 | N17: =Q16 | O17: =N17*VLOOKUP($B17,Funds!$A$5:$D$7,4,FALSE)/36500 | P17: =P16+O17-J17 | Q17: =M17-P17 | R17: =Q17/G17 | S17: =R17/R16-1
... A34: 46301 | B34: ALPHA_EQ | C34: =VLOOKUP($B34,Funds!$A$5:$B$7,2,FALSE) | D34: =G33 | E34: =SUMIFS(Transactions!$F:$F,Transactions!$C:$C,$B34,Transactions!$B:$B,$A34,Transactions!$D:$D,"SUBSCRIPTION") | F34: =-SUMIFS(Transactions!$F:$F,Transactions!$C:$C,$B34,Transactions!$B:$B,$A34,Transactions!$D:$D,"REDEMPTION") | G34: =D34+E34+F34 | H34: =K33 | I34: =SUMIFS(Transactions!$I:$I,Transactions!$C:$C,$B34,Transactions!$B:$B,$A34) | J34: =IF($A34=EOMONTH($A34,0),P33+O34,0) | K34: =H34+I34-J34 | L34: 1.0175837e+08 | M34: =K34+L34 | N34: =Q33 | O34: =N34*VLOOKUP($B34,Funds!$A$5:$D$7,4,FALSE)/36500 | P34: =P33+O34-J34 | Q34: =M34-P34 | R34: =Q34/G34 | S34: =R34/R33-1
A35: 46260 | B35: BETA_DEBT | C35: =VLOOKUP($B35,Funds!$A$5:$B$7,2,FALSE) | D35: =VLOOKUP($B35,Funds!$A$5:$F$7,6,FALSE) | E35: =SUMIFS(Transactions!$F:$F,Transactions!$C:$C,$B35,Transactions!$B:$B,$A35,Transactions!$D:$D,"SUBSCRIPTION") | F35: =-SUMIFS(Transactions!$F:$F,Transactions!$C:$C,$B35,Transactions!$B:$B,$A35,Transactions!$D:$D,"REDEMPTION") | G35: =D35+E35+F35 | H35: =VLOOKUP($B35,Funds!$A$5:$G$7,7,FALSE) | I35: =SUMIFS(Transactions!$I:$I,Transactions!$C:$C,$B35,Transactions!$B:$B,$A35) | J35: =IF($A35=EOMONTH($A35,0),O35,0) | K35: =H35+I35-J35 | L35: 1.9046311e+08 | M35: =K35+L35 | N35: =VLOOKUP($B35,Funds!$A$5:$E$7,5,FALSE)*VLOOKUP($B35,Funds!$A$5:$F$7,6,FALSE) | O35: =N35*VLOOKUP($B35,Funds!$A$5:$D$7,4,FALSE)/36500 | P35: =O35-J35 | Q35: =M35-P35 | R35: =Q35/G35 | S35: =R35/VLOOKUP($B35,Funds!$A$5:$E$7,5,FALSE)-1
A36: 46261 | B36: BETA_DEBT | C36: =VLOOKUP($B36,Funds!$A$5:$B$7,2,FALSE) | D36: =G35 | E36: =SUMIFS(Transactions!$F:$F,Transactions!$C:$C,$B36,Transactions!$B:$B,$A36,Transactions!$D:$D,"SUBSCRIPTION") | F36: =-SUMIFS(Transactions!$F:$F,Transactions!$C:$C,$B36,Transactions!$B:$B,$A36,Transactions!$D:$D,"REDEMPTION") | G36: =D36+E36+F36 | H36: =K35 | I36: =SUMIFS(Transactions!$I:$I,Transactions!$C:$C,$B36,Transactions!$B:$B,$A36) | J36: =IF($A36=EOMONTH($A36,0),P35+O36,0) | K36: =H36+I36-J36 | L36: 1.9066224e+08 | M36: =K36+L36 | N36: =Q35 | O36: =N36*VLOOKUP($B36,Funds!$A$5:$D$7,4,FALSE)/36500 | P36: =P35+O36-J36 | Q36: =M36-P36 | R36: =Q36/G36 | S36: =R36/R35-1
A37: 46262 | B37: BETA_DEBT | C37: =VLOOKUP($B37,Funds!$A$5:$B$7,2,FALSE) | D37: =G36 | E37: =SUMIFS(Transactions!$F:$F,Transactions!$C:$C,$B37,Transactions!$B:$B,$A37,Transactions!$D:$D,"SUBSCRIPTION") | F37: =-SUMIFS(Transactions!$F:$F,Transactions!$C:$C,$B37,Transactions!$B:$B,$A37,Transactions!$D:$D,"REDEMPTION") | G37: =D37+E37+F37 | H37: =K36 | I37: =SUMIFS(Transactions!$I:$I,Transactions!$C:$C,$B37,Transactions!$B:$B,$A37) | J37: =IF($A37=EOMONTH($A37,0),P36+O37,0) | K37: =H37+I37-J37 | L37: 1.9100028e+08 | M37: =K37+L37 | N37: =Q36 | O37: =N37*VLOOKUP($B37,Funds!$A$5:$D$7,4,FALSE)/36500 | P37: =P36+O37-J37 | Q37: =M37-P37 | R37: =Q37/G37 | S37: =R37/R36-1
A38: 46265 | B38: BETA_DEBT | C38: =VLOOKUP($B38,Funds!$A$5:$B$7,2,FALSE) | D38: =G37 | E38: =SUMIFS(Transactions!$F:$F,Transactions!$C:$C,$B38,Transactions!$B:$B,$A38,Transactions!$D:$D,"SUBSCRIPTION") | F38: =-SUMIFS(Transactions!$F:$F,Transactions!$C:$C,$B38,Transactions!$B:$B,$A38,Transactions!$D:$D,"REDEMPTION") | G38: =D38+E38+F38 | H38: =K37 | I38: =SUMIFS(Transactions!$I:$I,Transactions!$C:$C,$B38,Transactions!$B:$B,$A38) | J38: =IF($A38=EOMONTH($A38,0),P37+O38,0) | K38: =H38+I38-J38 | L38: 1.9445443e+08 | M38: =K38+L38 | N38: =Q37 | O38: =N38*VLOOKUP($B38,Funds!$A$5:$D$7,4,FALSE)/36500 | P38: =P37+O38-J38 | Q38: =M38-P38 | R38: =Q38/G38 | S38: =R38/R37-1
A39: 46266 | B39: BETA_DEBT | C39: =VLOOKUP($B39,Funds!$A$5:$B$7,2,FALSE) | D39: =G38 | E39: =SUMIFS(Transactions!$F:$F,Transactions!$C:$C,$B39,Transactions!$B:$B,$A39,Transactions!$D:$D,"SUBSCRIPTION") | F39: =-SUMIFS(Transactions!$F:$F,Transactions!$C:$C,$B39,Transactions!$B:$B,$A39,Transactions!$D:$D,"REDEMPTION") | G39: =D39+E39+F39 | H39: =K38 | I39: =SUMIFS(Transactions!$I:$I,Transactions!$C:$C,$B39,Transactions!$B:$B,$A39) | J39: =IF($A39=EOMONTH($A39,0),P38+O39,0) | K39: =H39+I39-J39 | L39: 1.9416296e+08 | M39: =K39+L39 | N39: =Q38 | O39: =N39*VLOOKUP($B39,Funds!$A$5:$D$7,4,FALSE)/36500 | P39: =P38+O39-J39 | Q39: =M39-P39 | R39: =Q39/G39 | S39: =R39/R38-1
A40: 46267 | B40: BETA_DEBT | C40: =VLOOKUP($B40,Funds!$A$5:$B$7,2,FALSE) | D40: =G39 | E40: =SUMIFS(Transactions!$F:$F,Transactions!$C:$C,$B40,Transactions!$B:$B,$A40,Transactions!$D:$D,"SUBSCRIPTION") | F40: =-SUMIFS(Transactions!$F:$F,Transactions!$C:$C,$B40,Transactions!$B:$B,$A40,Transactions!$D:$D,"REDEMPTION") | G40: =D40+E40+F40 | H40: =K39 | I40: =SUMIFS(Transactions!$I:$I,Transactions!$C:$C,$B40,Transactions!$B:$B,$A40) | J40: =IF($A40=EOMONTH($A40,0),P39+O40,0) | K40: =H40+I40-J40 | L40: 1.9360469e+08 | M40: =K40+L40 | N40: =Q39 | O40: =N40*VLOOKUP($B40,Funds!$A$5:$D$7,4,FALSE)/36500 | P40: =P39+O40-J40 | Q40: =M40-P40 | R40: =Q40/G40 | S40: =R40/R39-1
A41: 46268 | B41: BETA_DEBT | C41: =VLOOKUP($B41,Funds!$A$5:$B$7,2,FALSE) | D41: =G40 | E41: =SUMIFS(Transactions!$F:$F,Transactions!$C:$C,$B41,Transactions!$B:$B,$A41,Transactions!$D:$D,"SUBSCRIPTION") | F41: =-SUMIFS(Transactions!$F:$F,Transactions!$C:$C,$B41,Transactions!$B:$B,$A41,Transactions!$D:$D,"REDEMPTION") | G41: =D41+E41+F41 | H41: =K40 | I41: =SUMIFS(Transactions!$I:$I,Transactions!$C:$C,$B41,Transactions!$B:$B,$A41) | J41: =IF($A41=EOMONTH($A41,0),P40+O41,0) | K41: =H41+I41-J41 | L41: 1.9383421e+08 | M41: =K41+L41 | N41: =Q40 | O41: =N41*VLOOKUP($B41,Funds!$A$5:$D$7,4,FALSE)/36500 | P41: =P40+O41-J41 | Q41: =M41-P41 | R41: =Q41/G41 | S41: =R41/R40-1
A42: 46269 | B42: BETA_DEBT | C42: =VLOOKUP($B42,Funds!$A$5:$B$7,2,FALSE) | D42: =G41 | E42: =SUMIFS(Transactions!$F:$F,Transactions!$C:$C,$B42,Transactions!$B:$B,$A42,Transactions!$D:$D,"SUBSCRIPTION") | F42: =-SUMIFS(Transactions!$F:$F,Transactions!$C:$C,$B42,Transactions!$B:$B,$A42,Transactions!$D:$D,"REDEMPTION") | G42: =D42+E42+F42 | H42: =K41 | I42: =SUMIFS(Transactions!$I:$I,Transactions!$C:$C,$B42,Transactions!$B:$B,$A42) | J42: =IF($A42=EOMONTH($A42,0),P41+O42,0) | K42: =H42+I42-J42 | L42: 1.9413673e+08 | M42: =K42+L42 | N42: =Q41 | O42: =N42*VLOOKUP($B42,Funds!$A$5:$D$7,4,FALSE)/36500 | P42: =P41+O42-J42 | Q42: =M42-P42 | R42: =Q42/G42 | S42: =R42/R41-1
A43: 46272 | B43: BETA_DEBT | C43: =VLOOKUP($B43,Funds!$A$5:$B$7,2,FALSE) | D43: =G42 | E43: =SUMIFS(Transactions!$F:$F,Transactions!$C:$C,$B43,Transactions!$B:$B,$A43,Transactions!$D:$D,"SUBSCRIPTION") | F43: =-SUMIFS(Transactions!$F:$F,Transactions!$C:$C,$B43,Transactions!$B:$B,$A43,Transactions!$D:$D,"REDEMPTION") | G43: =D43+E43+F43 | H43: =K42 | I43: =SUMIFS(Transactions!$I:$I,Transactions!$C:$C,$B43,Transactions!$B:$B,$A43) | J43: =IF($A43=EOMONTH($A43,0),P42+O43,0) | K43: =H43+I43-J43 | L43: 1.939475e+08 | M43: =K43+L43 | N43: =Q42 | O43: =N43*VLOOKUP($B43,Funds!$A$5:$D$7,4,FALSE)/36500 | P43: =P42+O43-J43 | Q43: =M43-P43 | R43: =Q43/G43 | S43: =R43/R42-1
A44: 46273 | B44: BETA_DEBT | C44: =VLOOKUP($B44,Funds!$A$5:$B$7,2,FALSE) | D44: =G43 | E44: =SUMIFS(Transactions!$F:$F,Transactions!$C:$C,$B44,Transactions!$B:$B,$A44,Transactions!$D:$D,"SUBSCRIPTION") | F44: =-SUMIFS(Transactions!$F:$F,Transactions!$C:$C,$B44,Transactions!$B:$B,$A44,Transactions!$D:$D,"REDEMPTION") | G44: =D44+E44+F44 | H44: =K43 | I44: =SUMIFS(Transactions!$I:$I,Transactions!$C:$C,$B44,Transactions!$B:$B,$A44) | J44: =IF($A44=EOMONTH($A44,0),P43+O44,0) | K44: =H44+I44-J44 | L44: 1.9360486e+08 | M44: =K44+L44 | N44: =Q43 | O44: =N44*VLOOKUP($B44,Funds!$A$5:$D$7,4,FALSE)/36500 | P44: =P43+O44-J44 | Q44: =M44-P44 | R44: =Q44/G44 | S44: =R44/R43-1
A45: 46274 | B45: BETA_DEBT | C45: =VLOOKUP($B45,Funds!$A$5:$B$7,2,FALSE) | D45: =G44 | E45: =SUMIFS(Transactions!$F:$F,Transactions!$C:$C,$B45,Transactions!$B:$B,$A45,Transactions!$D:$D,"SUBSCRIPTION") | F45: =-SUMIFS(Transactions!$F:$F,Transactions!$C:$C,$B45,Transactions!$B:$B,$A45,Transactions!$D:$D,"REDEMPTION") | G45: =D45+E45+F45 | H45: =K44 | I45: =SUMIFS(Transactions!$I:$I,Transactions!$C:$C,$B45,Transactions!$B:$B,$A45) | J45: =IF($A45=EOMONTH($A45,0),P44+O45,0) | K45: =H45+I45-J45 | L45: 1.9353329e+08 | M45: =K45+L45 | N45: =Q44 | O45: =N45*VLOOKUP($B45,Funds!$A$5:$D$7,4,FALSE)/36500 | P45: =P44+O45-J45 | Q45: =M45-P45 | R45: =Q45/G45 | S45: =R45/R44-1
A46: 46275 | B46: BETA_DEBT | C46: =VLOOKUP($B46,Funds!$A$5:$B$7,2,FALSE) | D46: =G45 | E46: =SUMIFS(Transactions!$F:$F,Transactions!$C:$C,$B46,Transactions!$B:$B,$A46,Transactions!$D:$D,"SUBSCRIPTION") | F46: =-SUMIFS(Transactions!$F:$F,Transactions!$C:$C,$B46,Transactions!$B:$B,$A46,Transactions!$D:$D,"REDEMPTION") | G46: =D46+E46+F46 | H46: =K45 | I46: =SUMIFS(Transactions!$I:$I,Transactions!$C:$C,$B46,Transactions!$B:$B,$A46) | J46: =IF($A46=EOMONTH($A46,0),P45+O46,0) | K46: =H46+I46-J46 | L46: 1.9341548e+08 | M46: =K46+L46 | N46: =Q45 | O46: =N46*VLOOKUP($B46,Funds!$A$5:$D$7,4,FALSE)/36500 | P46: =P45+O46-J46 | Q46: =M46-P46 | R46: =Q46/G46 | S46: =R46/R45-1
A47: 46276 | B47: BETA_DEBT | C47: =VLOOKUP($B47,Funds!$A$5:$B$7,2,FALSE) | D47: =G46 | E47: =SUMIFS(Transactions!$F:$F,Transactions!$C:$C,$B47,Transactions!$B:$B,$A47,Transactions!$D:$D,"SUBSCRIPTION") | F47: =-SUMIFS(Transactions!$F:$F,Transactions!$C:$C,$B47,Transactions!$B:$B,$A47,Transactions!$D:$D,"REDEMPTION") | G47: =D47+E47+F47 | H47: =K46 | I47: =SUMIFS(Transactions!$I:$I,Transactions!$C:$C,$B47,Transactions!$B:$B,$A47) | J47: =IF($A47=EOMONTH($A47,0),P46+O47,0) | K47: =H47+I47-J47 | L47: 1.9292029e+08 | M47: =K47+L47 | N47: =Q46 | O47: =N47*VLOOKUP($B47,Funds!$A$5:$D$7,4,FALSE)/36500 | P47: =P46+O47-J47 | Q47: =M47-P47 | R47: =Q47/G47 | S47: =R47/R46-1
... A64: 46301 | B64: BETA_DEBT | C64: =VLOOKUP($B64,Funds!$A$5:$B$7,2,FALSE) | D64: =G63 | E64: =SUMIFS(Transactions!$F:$F,Transactions!$C:$C,$B64,Transactions!$B:$B,$A64,Transactions!$D:$D,"SUBSCRIPTION") | F64: =-SUMIFS(Transactions!$F:$F,Transactions!$C:$C,$B64,Transactions!$B:$B,$A64,Transactions!$D:$D,"REDEMPTION") | G64: =D64+E64+F64 | H64: =K63 | I64: =SUMIFS(Transactions!$I:$I,Transactions!$C:$C,$B64,Transactions!$B:$B,$A64) | J64: =IF($A64=EOMONTH($A64,0),P63+O64,0) | K64: =H64+I64-J64 | L64: 1.7981868e+08 | M64: =K64+L64 | N64: =Q63 | O64: =N64*VLOOKUP($B64,Funds!$A$5:$D$7,4,FALSE)/36500 | P64: =P63+O64-J64 | Q64: =M64-P64 | R64: =Q64/G64 | S64: =R64/R63-1
A65: 46260 | B65: GAMMA_BAL | C65: =VLOOKUP($B65,Funds!$A$5:$B$7,2,FALSE) | D65: =VLOOKUP($B65,Funds!$A$5:$F$7,6,FALSE) | E65: =SUMIFS(Transactions!$F:$F,Transactions!$C:$C,$B65,Transactions!$B:$B,$A65,Transactions!$D:$D,"SUBSCRIPTION") | F65: =-SUMIFS(Transactions!$F:$F,Transactions!$C:$C,$B65,Transactions!$B:$B,$A65,Transactions!$D:$D,"REDEMPTION") | G65: =D65+E65+F65 | H65: =VLOOKUP($B65,Funds!$A$5:$G$7,7,FALSE) | I65: =SUMIFS(Transactions!$I:$I,Transactions!$C:$C,$B65,Transactions!$B:$B,$A65) | J65: =IF($A65=EOMONTH($A65,0),O65,0) | K65: =H65+I65-J65 | L65: 1.3609937e+08 | M65: =K65+L65 | N65: =VLOOKUP($B65,Funds!$A$5:$E$7,5,FALSE)*VLOOKUP($B65,Funds!$A$5:$F$7,6,FALSE) | O65: =N65*VLOOKUP($B65,Funds!$A$5:$D$7,4,FALSE)/36500 | P65: =O65-J65 | Q65: =M65-P65 | R65: =Q65/G65 | S65: =R65/VLOOKUP($B65,Funds!$A$5:$E$7,5,FALSE)-1
A66: 46261 | B66: GAMMA_BAL | C66: =VLOOKUP($B66,Funds!$A$5:$B$7,2,FALSE) | D66: =G65 | E66: =SUMIFS(Transactions!$F:$F,Transactions!$C:$C,$B66,Transactions!$B:$B,$A66,Transactions!$D:$D,"SUBSCRIPTION") | F66: =-SUMIFS(Transactions!$F:$F,Transactions!$C:$C,$B66,Transactions!$B:$B,$A66,Transactions!$D:$D,"REDEMPTION") | G66: =D66+E66+F66 | H66: =K65 | I66: =SUMIFS(Transactions!$I:$I,Transactions!$C:$C,$B66,Transactions!$B:$B,$A66) | J66: =IF($A66=EOMONTH($A66,0),P65+O66,0) | K66: =H66+I66-J66 | L66: 1.3560168e+08 | M66: =K66+L66 | N66: =Q65 | O66: =N66*VLOOKUP($B66,Funds!$A$5:$D$7,4,FALSE)/36500 | P66: =P65+O66-J66 | Q66: =M66-P66 | R66: =Q66/G66 | S66: =R66/R65-1
A67: 46262 | B67: GAMMA_BAL | C67: =VLOOKUP($B67,Funds!$A$5:$B$7,2,FALSE) | D67: =G66 | E67: =SUMIFS(Transactions!$F:$F,Transactions!$C:$C,$B67,Transactions!$B:$B,$A67,Transactions!$D:$D,"SUBSCRIPTION") | F67: =-SUMIFS(Transactions!$F:$F,Transactions!$C:$C,$B67,Transactions!$B:$B,$A67,Transactions!$D:$D,"REDEMPTION") | G67: =D67+E67+F67 | H67: =K66 | I67: =SUMIFS(Transactions!$I:$I,Transactions!$C:$C,$B67,Transactions!$B:$B,$A67) | J67: =IF($A67=EOMONTH($A67,0),P66+O67,0) | K67: =H67+I67-J67 | L67: 1.3341077e+08 | M67: =K67+L67 | N67: =Q66 | O67: =N67*VLOOKUP($B67,Funds!$A$5:$D$7,4,FALSE)/36500 | P67: =P66+O67-J67 | Q67: =M67-P67 | R67: =Q67/G67 | S67: =R67/R66-1
A68: 46265 | B68: GAMMA_BAL | C68: =VLOOKUP($B68,Funds!$A$5:$B$7,2,FALSE) | D68: =G67 | E68: =SUMIFS(Transactions!$F:$F,Transactions!$C:$C,$B68,Transactions!$B:$B,$A68,Transactions!$D:$D,"SUBSCRIPTION") | F68: =-SUMIFS(Transactions!$F:$F,Transactions!$C:$C,$B68,Transactions!$B:$B,$A68,Transactions!$D:$D,"REDEMPTION") | G68: =D68+E68+F68 | H68: =K67 | I68: =SUMIFS(Transactions!$I:$I,Transactions!$C:$C,$B68,Transactions!$B:$B,$A68) | J68: =IF($A68=EOMONTH($A68,0),P67+O68,0) | K68: =H68+I68-J68 | L68: 1.3198882e+08 | M68: =K68+L68 | N68: =Q67 | O68: =N68*VLOOKUP($B68,Funds!$A$5:$D$7,4,FALSE)/36500 | P68: =P67+O68-J68 | Q68: =M68-P68 | R68: =Q68/G68 | S68: =R68/R67-1
A69: 46266 | B69: GAMMA_BAL | C69: =VLOOKUP($B69,Funds!$A$5:$B$7,2,FALSE) | D69: =G68 | E69: =SUMIFS(Transactions!$F:$F,Transactions!$C:$C,$B69,Transactions!$B:$B,$A69,Transactions!$D:$D,"SUBSCRIPTION") | F69: =-SUMIFS(Transactions!$F:$F,Transactions!$C:$C,$B69,Transactions!$B:$B,$A69,Transactions!$D:$D,"REDEMPTION") | G69: =D69+E69+F69 | H69: =K68 | I69: =SUMIFS(Transactions!$I:$I,Transactions!$C:$C,$B69,Transactions!$B:$B,$A69) | J69: =IF($A69=EOMONTH($A69,0),P68+O69,0) | K69: =H69+I69-J69 | L69: 1.2721951e+08 | M69: =K69+L69 | N69: =Q68 | O69: =N69*VLOOKUP($B69,Funds!$A$5:$D$7,4,FALSE)/36500 | P69: =P68+O69-J69 | Q69: =M69-P69 | R69: =Q69/G69 | S69: =R69/R68-1
A70: 46267 | B70: GAMMA_BAL | C70: =VLOOKUP($B70,Funds!$A$5:$B$7,2,FALSE) | D70: =G69 | E70: =SUMIFS(Transactions!$F:$F,Transactions!$C:$C,$B70,Transactions!$B:$B,$A70,Transactions!$D:$D,"SUBSCRIPTION") | F70: =-SUMIFS(Transactions!$F:$F,Transactions!$C:$C,$B70,Transactions!$B:$B,$A70,Transactions!$D:$D,"REDEMPTION") | G70: =D70+E70+F70 | H70: =K69 | I70: =SUMIFS(Transactions!$I:$I,Transactions!$C:$C,$B70,Transactions!$B:$B,$A70) | J70: =IF($A70=EOMONTH($A70,0),P69+O70,0) | K70: =H70+I70-J70 | L70: 1.2921532e+08 | M70: =K70+L70 | N70: =Q69 | O70: =N70*VLOOKUP($B70,Funds!$A$5:$D$7,4,FALSE)/36500 | P70: =P69+O70-J70 | Q70: =M70-P70 | R70: =Q70/G70 | S70: =R70/R69-1
A71: 46268 | B71: GAMMA_BAL | C71: =VLOOKUP($B71,Funds!$A$5:$B$7,2,FALSE) | D71: =G70 | E71: =SUMIFS(Transactions!$F:$F,Transactions!$C:$C,$B71,Transactions!$B:$B,$A71,Transactions!$D:$D,"SUBSCRIPTION") | F71: =-SUMIFS(Transactions!$F:$F,Transactions!$C:$C,$B71,Transactions!$B:$B,$A71,Transactions!$D:$D,"REDEMPTION") | G71: =D71+E71+F71 | H71: =K70 | I71: =SUMIFS(Transactions!$I:$I,Transactions!$C:$C,$B71,Transactions!$B:$B,$A71) | J71: =IF($A71=EOMONTH($A71,0),P70+O71,0) | K71: =H71+I71-J71 | L71: 1.2590566e+08 | M71: =K71+L71 | N71: =Q70 | O71: =N71*VLOOKUP($B71,Funds!$A$5:$D$7,4,FALSE)/36500 | P71: =P70+O71-J71 | Q71: =M71-P71 | R71: =Q71/G71 | S71: =R71/R70-1
A72: 46269 | B72: GAMMA_BAL | C72: =VLOOKUP($B72,Funds!$A$5:$B$7,2,FALSE) | D72: =G71 | E72: =SUMIFS(Transactions!$F:$F,Transactions!$C:$C,$B72,Transactions!$B:$B,$A72,Transactions!$D:$D,"SUBSCRIPTION") | F72: =-SUMIFS(Transactions!$F:$F,Transactions!$C:$C,$B72,Transactions!$B:$B,$A72,Transactions!$D:$D,"REDEMPTION") | G72: =D72+E72+F72 | H72: =K71 | I72: =SUMIFS(Transactions!$I:$I,Transactions!$C:$C,$B72,Transactions!$B:$B,$A72) | J72: =IF($A72=EOMONTH($A72,0),P71+O72,0) | K72: =H72+I72-J72 | L72: 1.2872239e+08 | M72: =K72+L72 | N72: =Q71 | O72: =N72*VLOOKUP($B72,Funds!$A$5:$D$7,4,FALSE)/36500 | P72: =P71+O72-J72 | Q72: =M72-P72 | R72: =Q72/G72 | S72: =R72/R71-1
A73: 46272 | B73: GAMMA_BAL | C73: =VLOOKUP($B73,Funds!$A$5:$B$7,2,FALSE) | D73: =G72 | E73: =SUMIFS(Transactions!$F:$F,Transactions!$C:$C,$B73,Transactions!$B:$B,$A73,Transactions!$D:$D,"SUBSCRIPTION") | F73: =-SUMIFS(Transactions!$F:$F,Transactions!$C:$C,$B73,Transactions!$B:$B,$A73,Transactions!$D:$D,"REDEMPTION") | G73: =D73+E73+F73 | H73: =K72 | I73: =SUMIFS(Transactions!$I:$I,Transactions!$C:$C,$B73,Transactions!$B:$B,$A73) | J73: =IF($A73=EOMONTH($A73,0),P72+O73,0) | K73: =H73+I73-J73 | L73: 1.3308234e+08 | M73: =K73+L73 | N73: =Q72 | O73: =N73*VLOOKUP($B73,Funds!$A$5:$D$7,4,FALSE)/36500 | P73: =P72+O73-J73 | Q73: =M73-P73 | R73: =Q73/G73 | S73: =R73/R72-1
...

Sheet ChartData
A1: CHART SOURCE DATA (LIVE FORMULAS)
A2: Feeds the Dashboard charts
A4: date | B4: ALPHA_EQ | C4: BETA_DEBT | D4: GAMMA_BAL | F4: fund | G4: AUM (INR Cr) | I4: Status | J4: Items
A5: 46260 | B5: =SUMIFS(NAV_Calc!$R:$R,NAV_Calc!$B:$B,B$4,NAV_Calc!$A:$A,$A5) | C5: =SUMIFS(NAV_Calc!$R:$R,NAV_Calc!$B:$B,C$4,NAV_Calc!$A:$A,$A5) | D5: =SUMIFS(NAV_Calc!$R:$R,NAV_Calc!$B:$B,D$4,NAV_Calc!$A:$A,$A5) | F5: ALPHA_EQ | G5: =SUMIFS(NAV_Calc!$Q:$Q,NAV_Calc!$B:$B,$F5,NAV_Calc!$A:$A,Dashboard!$C$4)/10000000 | I5: Matched | J5: =COUNTIF(Recon_Holdings!$I$5:$I$21,"MATCHED")+COUNTIF(Recon_Cash!$E$5:$E$7,"MATCHED")+COUNTIF(Recon_NAV!$F$5:$F$94,"MATCHED")
A6: 46261 | B6: =SUMIFS(NAV_Calc!$R:$R,NAV_Calc!$B:$B,B$4,NAV_Calc!$A:$A,$A6) | C6: =SUMIFS(NAV_Calc!$R:$R,NAV_Calc!$B:$B,C$4,NAV_Calc!$A:$A,$A6) | D6: =SUMIFS(NAV_Calc!$R:$R,NAV_Calc!$B:$B,D$4,NAV_Calc!$A:$A,$A6) | F6: BETA_DEBT | G6: =SUMIFS(NAV_Calc!$Q:$Q,NAV_Calc!$B:$B,$F6,NAV_Calc!$A:$A,Dashboard!$C$4)/10000000 | I6: Breaks | J6: =COUNTA(Recon_Holdings!$A$5:$A$21)+COUNTA(Recon_Cash!$A$5:$A$7)+COUNTA(Recon_NAV!$A$5:$A$94)-J5
A7: 46262 | B7: =SUMIFS(NAV_Calc!$R:$R,NAV_Calc!$B:$B,B$4,NAV_Calc!$A:$A,$A7) | C7: =SUMIFS(NAV_Calc!$R:$R,NAV_Calc!$B:$B,C$4,NAV_Calc!$A:$A,$A7) | D7: =SUMIFS(NAV_Calc!$R:$R,NAV_Calc!$B:$B,D$4,NAV_Calc!$A:$A,$A7) | F7: GAMMA_BAL | G7: =SUMIFS(NAV_Calc!$Q:$Q,NAV_Calc!$B:$B,$F7,NAV_Calc!$A:$A,Dashboard!$C$4)/10000000
A8: 46265 | B8: =SUMIFS(NAV_Calc!$R:$R,NAV_Calc!$B:$B,B$4,NAV_Calc!$A:$A,$A8) | C8: =SUMIFS(NAV_Calc!$R:$R,NAV_Calc!$B:$B,C$4,NAV_Calc!$A:$A,$A8) | D8: =SUMIFS(NAV_Calc!$R:$R,NAV_Calc!$B:$B,D$4,NAV_Calc!$A:$A,$A8)
A9: 46266 | B9: =SUMIFS(NAV_Calc!$R:$R,NAV_Calc!$B:$B,B$4,NAV_Calc!$A:$A,$A9) | C9: =SUMIFS(NAV_Calc!$R:$R,NAV_Calc!$B:$B,C$4,NAV_Calc!$A:$A,$A9) | D9: =SUMIFS(NAV_Calc!$R:$R,NAV_Calc!$B:$B,D$4,NAV_Calc!$A:$A,$A9)
A10: 46267 | B10: =SUMIFS(NAV_Calc!$R:$R,NAV_Calc!$B:$B,B$4,NAV_Calc!$A:$A,$A10) | C10: =SUMIFS(NAV_Calc!$R:$R,NAV_Calc!$B:$B,C$4,NAV_Calc!$A:$A,$A10) | D10: =SUMIFS(NAV_Calc!$R:$R,NAV_Calc!$B:$B,D$4,NAV_Calc!$A:$A,$A10)
A11: 46268 | B11: =SUMIFS(NAV_Calc!$R:$R,NAV_Calc!$B:$B,B$4,NAV_Calc!$A:$A,$A11) | C11: =SUMIFS(NAV_Calc!$R:$R,NAV_Calc!$B:$B,C$4,NAV_Calc!$A:$A,$A11) | D11: =SUMIFS(NAV_Calc!$R:$R,NAV_Calc!$B:$B,D$4,NAV_Calc!$A:$A,$A11)
A12: 46269 | B12: =SUMIFS(NAV_Calc!$R:$R,NAV_Calc!$B:$B,B$4,NAV_Calc!$A:$A,$A12) | C12: =SUMIFS(NAV_Calc!$R:$R,NAV_Calc!$B:$B,C$4,NAV_Calc!$A:$A,$A12) | D12: =SUMIFS(NAV_Calc!$R:$R,NAV_Calc!$B:$B,D$4,NAV_Calc!$A:$A,$A12)
A13: 46272 | B13: =SUMIFS(NAV_Calc!$R:$R,NAV_Calc!$B:$B,B$4,NAV_Calc!$A:$A,$A13) | C13: =SUMIFS(NAV_Calc!$R:$R,NAV_Calc!$B:$B,C$4,NAV_Calc!$A:$A,$A13) | D13: =SUMIFS(NAV_Calc!$R:$R,NAV_Calc!$B:$B,D$4,NAV_Calc!$A:$A,$A13)
A14: 46273 | B14: =SUMIFS(NAV_Calc!$R:$R,NAV_Calc!$B:$B,B$4,NAV_Calc!$A:$A,$A14) | C14: =SUMIFS(NAV_Calc!$R:$R,NAV_Calc!$B:$B,C$4,NAV_Calc!$A:$A,$A14) | D14: =SUMIFS(NAV_Calc!$R:$R,NAV_Calc!$B:$B,D$4,NAV_Calc!$A:$A,$A14)
A15: 46274 | B15: =SUMIFS(NAV_Calc!$R:$R,NAV_Calc!$B:$B,B$4,NAV_Calc!$A:$A,$A15) | C15: =SUMIFS(NAV_Calc!$R:$R,NAV_Calc!$B:$B,C$4,NAV_Calc!$A:$A,$A15) | D15: =SUMIFS(NAV_Calc!$R:$R,NAV_Calc!$B:$B,D$4,NAV_Calc!$A:$A,$A15)
A16: 46275 | B16: =SUMIFS(NAV_Calc!$R:$R,NAV_Calc!$B:$B,B$4,NAV_Calc!$A:$A,$A16) | C16: =SUMIFS(NAV_Calc!$R:$R,NAV_Calc!$B:$B,C$4,NAV_Calc!$A:$A,$A16) | D16: =SUMIFS(NAV_Calc!$R:$R,NAV_Calc!$B:$B,D$4,NAV_Calc!$A:$A,$A16)
A17: 46276 | B17: =SUMIFS(NAV_Calc!$R:$R,NAV_Calc!$B:$B,B$4,NAV_Calc!$A:$A,$A17) | C17: =SUMIFS(NAV_Calc!$R:$R,NAV_Calc!$B:$B,C$4,NAV_Calc!$A:$A,$A17) | D17: =SUMIFS(NAV_Calc!$R:$R,NAV_Calc!$B:$B,D$4,NAV_Calc!$A:$A,$A17)
A18: 46279 | B18: =SUMIFS(NAV_Calc!$R:$R,NAV_Calc!$B:$B,B$4,NAV_Calc!$A:$A,$A18) | C18: =SUMIFS(NAV_Calc!$R:$R,NAV_Calc!$B:$B,C$4,NAV_Calc!$A:$A,$A18) | D18: =SUMIFS(NAV_Calc!$R:$R,NAV_Calc!$B:$B,D$4,NAV_Calc!$A:$A,$A18)
A19: 46280 | B19: =SUMIFS(NAV_Calc!$R:$R,NAV_Calc!$B:$B,B$4,NAV_Calc!$A:$A,$A19) | C19: =SUMIFS(NAV_Calc!$R:$R,NAV_Calc!$B:$B,C$4,NAV_Calc!$A:$A,$A19) | D19: =SUMIFS(NAV_Calc!$R:$R,NAV_Calc!$B:$B,D$4,NAV_Calc!$A:$A,$A19)
... A34: 46301 | B34: =SUMIFS(NAV_Calc!$R:$R,NAV_Calc!$B:$B,B$4,NAV_Calc!$A:$A,$A34) | C34: =SUMIFS(NAV_Calc!$R:$R,NAV_Calc!$B:$B,C$4,NAV_Calc!$A:$A,$A34) | D34: =SUMIFS(NAV_Calc!$R:$R,NAV_Calc!$B:$B,D$4,NAV_Calc!$A:$A,$A34)

Sheet Recon_Holdings
A1: RECONCILIATION - HOLDINGS (BOOKS vs CUSTODIAN)
A2: Book qty = SUMIFS over Transactions up to the custodian statement date (live formula)
A4: fund_code | B4: symbol | C4: book_qty (formula) | D4: custodian_qty | E4: qty_diff | F4: book_price | G4: custodian_price | H4: price_var_pct | I4: recon_status | J4: impact_inr
A5: ALPHA_EQ | B5: HDFCBANK | C5: =SUMIFS(Transactions!$G:$G,Transactions!$C:$C,$A5,Transactions!$E:$E,$B5,Transactions!$B:$B,"<="&$M$5) | D5: 650 | E5: =IF($D5="","",$C5-$D5) | F5: 1707.0177 | G5: 1707.0177 | H5: =IF($G5="","",($G5-$F5)/$F5) | I5: =IF($D5="","MISSING_IN_CUSTODIAN",IF(ABS($E5)>$M$6,"QTY_BREAK",IF(ABS($H5)>$M$7,"PRICE_BREAK","MATCHED"))) | J5: =IF($I5="MATCHED",0,IF($I5="QTY_BREAK",ABS($E5)*$F5,IF($I5="PRICE_BREAK",ABS($G5-$F5)*$C5,$C5*$F5))) | L5: custodian_stmt_date | M5: 46300
A6: ALPHA_EQ | B6: ICICIBANK | C6: =SUMIFS(Transactions!$G:$G,Transactions!$C:$C,$A6,Transactions!$E:$E,$B6,Transactions!$B:$B,"<="&$M$5) | D6: 19600 | E6: =IF($D6="","",$C6-$D6) | F6: 1339.5522 | G6: 1339.5522 | H6: =IF($G6="","",($G6-$F6)/$F6) | I6: =IF($D6="","MISSING_IN_CUSTODIAN",IF(ABS($E6)>$M$6,"QTY_BREAK",IF(ABS($H6)>$M$7,"PRICE_BREAK","MATCHED"))) | J6: =IF($I6="MATCHED",0,IF($I6="QTY_BREAK",ABS($E6)*$F6,IF($I6="PRICE_BREAK",ABS($G6-$F6)*$C6,$C6*$F6))) | L6: qty_tolerance | M6: 0
A7: ALPHA_EQ | B7: INFY | C7: =SUMIFS(Transactions!$G:$G,Transactions!$C:$C,$A7,Transactions!$E:$E,$B7,Transactions!$B:$B,"<="&$M$5) | D7: 13900 | E7: =IF($D7="","",$C7-$D7) | F7: 1942.6906 | G7: 1942.6906 | H7: =IF($G7="","",($G7-$F7)/$F7) | I7: =IF($D7="","MISSING_IN_CUSTODIAN",IF(ABS($E7)>$M$6,"QTY_BREAK",IF(ABS($H7)>$M$7,"PRICE_BREAK","MATCHED"))) | J7: =IF($I7="MATCHED",0,IF($I7="QTY_BREAK",ABS($E7)*$F7,IF($I7="PRICE_BREAK",ABS($G7-$F7)*$C7,$C7*$F7))) | L7: price_tolerance | M7: 0.0001
A8: ALPHA_EQ | B8: ITC | C8: =SUMIFS(Transactions!$G:$G,Transactions!$C:$C,$A8,Transactions!$E:$E,$B8,Transactions!$B:$B,"<="&$M$5) | D8: 10700 | E8: =IF($D8="","",$C8-$D8) | F8: 474.2041 | G8: 474.2041 | H8: =IF($G8="","",($G8-$F8)/$F8) | I8: =IF($D8="","MISSING_IN_CUSTODIAN",IF(ABS($E8)>$M$6,"QTY_BREAK",IF(ABS($H8)>$M$7,"PRICE_BREAK","MATCHED"))) | J8: =IF($I8="MATCHED",0,IF($I8="QTY_BREAK",ABS($E8)*$F8,IF($I8="PRICE_BREAK",ABS($G8-$F8)*$C8,$C8*$F8)))
A9: ALPHA_EQ | B9: RELIANCE | C9: =SUMIFS(Transactions!$G:$G,Transactions!$C:$C,$A9,Transactions!$E:$E,$B9,Transactions!$B:$B,"<="&$M$5) | D9: 2100 | E9: =IF($D9="","",$C9-$D9) | F9: 1547.948 | G9: 1547.948 | H9: =IF($G9="","",($G9-$F9)/$F9) | I9: =IF($D9="","MISSING_IN_CUSTODIAN",IF(ABS($E9)>$M$6,"QTY_BREAK",IF(ABS($H9)>$M$7,"PRICE_BREAK","MATCHED"))) | J9: =IF($I9="MATCHED",0,IF($I9="QTY_BREAK",ABS($E9)*$F9,IF($I9="PRICE_BREAK",ABS($G9-$F9)*$C9,$C9*$F9)))
A10: ALPHA_EQ | B10: TCS | C10: =SUMIFS(Transactions!$G:$G,Transactions!$C:$C,$A10,Transactions!$E:$E,$B10,Transactions!$B:$B,"<="&$M$5) | D10: 9000 | E10: =IF($D10="","",$C10-$D10) | F10: 3834.4002 | G10: 3834.4002 | H10: =IF($G10="","",($G10-$F10)/$F10) | I10: =IF($D10="","MISSING_IN_CUSTODIAN",IF(ABS($E10)>$M$6,"QTY_BREAK",IF(ABS($H10)>$M$7,"PRICE_BREAK","MATCHED"))) | J10: =IF($I10="MATCHED",0,IF($I10="QTY_BREAK",ABS($E10)*$F10,IF($I10="PRICE_BREAK",ABS($G10-$F10)*$C10,$C10*$F10)))
A11: BETA_DEBT | B11: CP-TATA | C11: =SUMIFS(Transactions!$G:$G,Transactions!$C:$C,$A11,Transactions!$E:$E,$B11,Transactions!$B:$B,"<="&$M$5) | D11: 198400 | E11: =IF($D11="","",$C11-$D11) | F11: 100.5236 | G11: 100.5236 | H11: =IF($G11="","",($G11-$F11)/$F11) | I11: =IF($D11="","MISSING_IN_CUSTODIAN",IF(ABS($E11)>$M$6,"QTY_BREAK",IF(ABS($H11)>$M$7,"PRICE_BREAK","MATCHED"))) | J11: =IF($I11="MATCHED",0,IF($I11="QTY_BREAK",ABS($E11)*$F11,IF($I11="PRICE_BREAK",ABS($G11-$F11)*$C11,$C11*$F11)))
A12: BETA_DEBT | B12: GOI7.26-36 | C12: =SUMIFS(Transactions!$G:$G,Transactions!$C:$C,$A12,Transactions!$E:$E,$B12,Transactions!$B:$B,"<="&$M$5) | D12: 577200 | E12: =IF($D12="","",$C12-$D12) | F12: 103.1117 | G12: 103.1117 | H12: =IF($G12="","",($G12-$F12)/$F12) | I12: =IF($D12="","MISSING_IN_CUSTODIAN",IF(ABS($E12)>$M$6,"QTY_BREAK",IF(ABS($H12)>$M$7,"PRICE_BREAK","MATCHED"))) | J12: =IF($I12="MATCHED",0,IF($I12="QTY_BREAK",ABS($E12)*$F12,IF($I12="PRICE_BREAK",ABS($G12-$F12)*$C12,$C12*$F12)))
A13: BETA_DEBT | B13: GOI8.2-33 | C13: =SUMIFS(Transactions!$G:$G,Transactions!$C:$C,$A13,Transactions!$E:$E,$B13,Transactions!$B:$B,"<="&$M$5) | D13: 451200 | E13: =IF($D13="","",$C13-$D13) | F13: 109.1682 | G13: 109.1682 | H13: =IF($G13="","",($G13-$F13)/$F13) | I13: =IF($D13="","MISSING_IN_CUSTODIAN",IF(ABS($E13)>$M$6,"QTY_BREAK",IF(ABS($H13)>$M$7,"PRICE_BREAK","MATCHED"))) | J13: =IF($I13="MATCHED",0,IF($I13="QTY_BREAK",ABS($E13)*$F13,IF($I13="PRICE_BREAK",ABS($G13-$F13)*$C13,$C13*$F13)))
A14: BETA_DEBT | B14: NCD-REL | C14: =SUMIFS(Transactions!$G:$G,Transactions!$C:$C,$A14,Transactions!$E:$E,$B14,Transactions!$B:$B,"<="&$M$5) | E14: =IF($D14="","",$C14-$D14) | F14: 979.4889 | H14: =IF($G14="","",($G14-$F14)/$F14) | I14: =IF($D14="","MISSING_IN_CUSTODIAN",IF(ABS($E14)>$M$6,"QTY_BREAK",IF(ABS($H14)>$M$7,"PRICE_BREAK","MATCHED"))) | J14: =IF($I14="MATCHED",0,IF($I14="QTY_BREAK",ABS($E14)*$F14,IF($I14="PRICE_BREAK",ABS($G14-$F14)*$C14,$C14*$F14)))
A15: BETA_DEBT | B15: SDL-MH-32 | C15: =SUMIFS(Transactions!$G:$G,Transactions!$C:$C,$A15,Transactions!$E:$E,$B15,Transactions!$B:$B,"<="&$M$5) | D15: 286000 | E15: =IF($D15="","",$C15-$D15) | F15: 104.0976 | G15: 104.0976 | H15: =IF($G15="","",($G15-$F15)/$F15) | I15: =IF($D15="","MISSING_IN_CUSTODIAN",IF(ABS($E15)>$M$6,"QTY_BREAK",IF(ABS($H15)>$M$7,"PRICE_BREAK","MATCHED"))) | J15: =IF($I15="MATCHED",0,IF($I15="QTY_BREAK",ABS($E15)*$F15,IF($I15="PRICE_BREAK",ABS($G15-$F15)*$C15,$C15*$F15)))
A16: GAMMA_BAL | B16: GOI7.26-36 | C16: =SUMIFS(Transactions!$G:$G,Transactions!$C:$C,$A16,Transactions!$E:$E,$B16,Transactions!$B:$B,"<="&$M$5) | D16: 370900 | E16: =IF($D16="","",$C16-$D16) | F16: 103.1117 | G16: 103.1117 | H16: =IF($G16="","",($G16-$F16)/$F16) | I16: =IF($D16="","MISSING_IN_CUSTODIAN",IF(ABS($E16)>$M$6,"QTY_BREAK",IF(ABS($H16)>$M$7,"PRICE_BREAK","MATCHED"))) | J16: =IF($I16="MATCHED",0,IF($I16="QTY_BREAK",ABS($E16)*$F16,IF($I16="PRICE_BREAK",ABS($G16-$F16)*$C16,$C16*$F16)))
A17: GAMMA_BAL | B17: HDFCBANK | C17: =SUMIFS(Transactions!$G:$G,Transactions!$C:$C,$A17,Transactions!$E:$E,$B17,Transactions!$B:$B,"<="&$M$5) | D17: 11500 | E17: =IF($D17="","",$C17-$D17) | F17: 1707.0177 | G17: 1707.0177 | H17: =IF($G17="","",($G17-$F17)/$F17) | I17: =IF($D17="","MISSING_IN_CUSTODIAN",IF(ABS($E17)>$M$6,"QTY_BREAK",IF(ABS($H17)>$M$7,"PRICE_BREAK","MATCHED"))) | J17: =IF($I17="MATCHED",0,IF($I17="QTY_BREAK",ABS($E17)*$F17,IF($I17="PRICE_BREAK",ABS($G17-$F17)*$C17,$C17*$F17)))
A18: GAMMA_BAL | B18: INFY | C18: =SUMIFS(Transactions!$G:$G,Transactions!$C:$C,$A18,Transactions!$E:$E,$B18,Transactions!$B:$B,"<="&$M$5) | D18: 3900 | E18: =IF($D18="","",$C18-$D18) | F18: 1942.6906 | G18: 1942.6906 | H18: =IF($G18="","",($G18-$F18)/$F18) | I18: =IF($D18="","MISSING_IN_CUSTODIAN",IF(ABS($E18)>$M$6,"QTY_BREAK",IF(ABS($H18)>$M$7,"PRICE_BREAK","MATCHED"))) | J18: =IF($I18="MATCHED",0,IF($I18="QTY_BREAK",ABS($E18)*$F18,IF($I18="PRICE_BREAK",ABS($G18-$F18)*$C18,$C18*$F18)))
A19: GAMMA_BAL | B19: LT | C19: =SUMIFS(Transactions!$G:$G,Transactions!$C:$C,$A19,Transactions!$E:$E,$B19,Transactions!$B:$B,"<="&$M$5) | D19: 2200 | E19: =IF($D19="","",$C19-$D19) | F19: 2304.7428 | G19: 2304.7428 | H19: =IF($G19="","",($G19-$F19)/$F19) | I19: =IF($D19="","MISSING_IN_CUSTODIAN",IF(ABS($E19)>$M$6,"QTY_BREAK",IF(ABS($H19)>$M$7,"PRICE_BREAK","MATCHED"))) | J19: =IF($I19="MATCHED",0,IF($I19="QTY_BREAK",ABS($E19)*$F19,IF($I19="PRICE_BREAK",ABS($G19-$F19)*$C19,$C19*$F19)))
A20: GAMMA_BAL | B20: MARUTI | C20: =SUMIFS(Transactions!$G:$G,Transactions!$C:$C,$A20,Transactions!$E:$E,$B20,Transactions!$B:$B,"<="&$M$5) | D20: 19700 | E20: =IF($D20="","",$C20-$D20) | F20: 1732.9594 | G20: 1741.6242 | H20: =IF($G20="","",($G20-$F20)/$F20) | I20: =IF($D20="","MISSING_IN_CUSTODIAN",IF(ABS($E20)>$M$6,"QTY_BREAK",IF(ABS($H20)>$M$7,"PRICE_BREAK","MATCHED"))) | J20: =IF($I20="MATCHED",0,IF($I20="QTY_BREAK",ABS($E20)*$F20,IF($I20="PRICE_BREAK",ABS($G20-$F20)*$C20,$C20*$F20)))
A21: GAMMA_BAL | B21: SDL-MH-32 | C21: =SUMIFS(Transactions!$G:$G,Transactions!$C:$C,$A21,Transactions!$E:$E,$B21,Transactions!$B:$B,"<="&$M$5) | D21: 212900 | E21: =IF($D21="","",$C21-$D21) | F21: 104.0976 | G21: 104.0976 | H21: =IF($G21="","",($G21-$F21)/$F21) | I21: =IF($D21="","MISSING_IN_CUSTODIAN",IF(ABS($E21)>$M$6,"QTY_BREAK",IF(ABS($H21)>$M$7,"PRICE_BREAK","MATCHED"))) | J21: =IF($I21="MATCHED",0,IF($I21="QTY_BREAK",ABS($E21)*$F21,IF($I21="PRICE_BREAK",ABS($G21-$F21)*$C21,$C21*$F21)))

Sheet Recon_Cash
A1: RECONCILIATION - CASH (BOOKS vs BANK)
A2: Book cash = NAV_Calc cash_close on the bank statement date (live formula)
A4: fund_code | B4: book_cash (formula) | C4: bank_balance | D4: diff_inr | E4: recon_status | F4: impact_inr
A5: ALPHA_EQ | B5: =SUMIFS(NAV_Calc!$K:$K,NAV_Calc!$B:$B,$A5,NAV_Calc!$A:$A,$I$5) | C5: -4028329.9 | D5: =$B5-$C5 | E5: =IF(ABS($D5)<=$I$6,"MATCHED","AMOUNT_BREAK") | F5: =ABS($D5) | H5: bank_stmt_date | I5: 46301
A6: BETA_DEBT | B6: =SUMIFS(NAV_Calc!$K:$K,NAV_Calc!$B:$B,$A6,NAV_Calc!$A:$A,$I$5) | C6: 7459343.4 | D6: =$B6-$C6 | E6: =IF(ABS($D6)<=$I$6,"MATCHED","AMOUNT_BREAK") | F6: =ABS($D6) | H6: amount_tolerance | I6: 0.5
A7: GAMMA_BAL | B7: =SUMIFS(NAV_Calc!$K:$K,NAV_Calc!$B:$B,$A7,NAV_Calc!$A:$A,$I$5) | C7: 11778223 | D7: =$B7-$C7 | E7: =IF(ABS($D7)<=$I$6,"MATCHED","AMOUNT_BREAK") | F7: =ABS($D7)

Sheet Recon_NAV
A1: RECONCILIATION - NAV (ENGINE vs RTA PUBLISHED)
A2: Book NAV = NAV_Calc nav (live formula); tolerance in cell H5
A4: nav_date | B4: fund_code | C4: book_nav (formula) | D4: published_nav | E4: var_pct | F4: recon_status | G4: abs_var_pct
A5: 46260 | B5: ALPHA_EQ | C5: =SUMIFS(NAV_Calc!$R:$R,NAV_Calc!$B:$B,$B5,NAV_Calc!$A:$A,$A5) | D5: 9.943427 | E5: =($D5-$C5)/$C5 | F5: =IF(ABS($E5)<=$J$5,"MATCHED","NAV_BREAK") | G5: =ABS($E5) | I5: nav_tolerance -> | J5: 0.0005
A6: 46260 | B6: BETA_DEBT | C6: =SUMIFS(NAV_Calc!$R:$R,NAV_Calc!$B:$B,$B6,NAV_Calc!$A:$A,$A6) | D6: 9.99033 | E6: =($D6-$C6)/$C6 | F6: =IF(ABS($E6)<=$J$5,"MATCHED","NAV_BREAK") | G6: =ABS($E6)
A7: 46260 | B7: GAMMA_BAL | C7: =SUMIFS(NAV_Calc!$R:$R,NAV_Calc!$B:$B,$B7,NAV_Calc!$A:$A,$A7) | D7: 9.991182 | E7: =($D7-$C7)/$C7 | F7: =IF(ABS($E7)<=$J$5,"MATCHED","NAV_BREAK") | G7: =ABS($E7)
A8: 46261 | B8: ALPHA_EQ | C8: =SUMIFS(NAV_Calc!$R:$R,NAV_Calc!$B:$B,$B8,NAV_Calc!$A:$A,$A8) | D8: 9.936565 | E8: =($D8-$C8)/$C8 | F8: =IF(ABS($E8)<=$J$5,"MATCHED","NAV_BREAK") | G8: =ABS($E8)
